Workbook
Name NativeTimeline_OrderDate: #N/A
Name Slicer_Product: #N/A

Sheet Sales
A1: OrderID | B1: OrderDate | C1: Month | D1: ProductID | E1: AgentID | F1: Quantity | G1: UnitPrice | H1: Total Revenue | I1: Gross Profit By 30% | J1: Profit Margin | K1: Product | L1: Category | M1: Sales Agent | N1: Region
A2: 1 | B2: 45430 | C2: =TEXT(Table2[[#This Row],[OrderDate]],"mmm") -> May | D2: 2 | E2: 3 | F2: 8 | G2: 399679 | H2: =G2*F2 -> 3197432 | I2: =Table2[[#This Row],[Total Revenue]]*0.3 -> 959229.6 | J2: =I2/H2 -> 0.3 | K2: =VLOOKUP(Table2[[#This Row],[ProductID]],Products!$A$1:C6,2) -> Phone | L2: =VLOOKUP(D2,Products!$A$1:C6,3) -> Electronics | M2: =VLOOKUP(Table2[[#This Row],[AgentID]],Sales_Agents!$A$1:C5,2) -> Chinedu | N2: =VLOOKUP(Table2[[#This Row],[AgentID]],Sales_Agents!$A$1:C5,3) -> South
A3: 2 | B3: 45460 | C3: =TEXT(Table2[[#This Row],[OrderDate]],"mmm") -> Jun | D3: 4 | E3: 3 | F3: 16 | G3: 166443 | H3: =G3*F3 -> 2663088 | I3: =Table2[[#This Row],[Total Revenue]]*0.3 -> 798926.4 | J3: =I3/H3 -> 0.3 | K3: =VLOOKUP(Table2[[#This Row],[ProductID]],Products!$A$1:C7,2) -> Printer | L3: =VLOOKUP(D3,Products!$A$1:C7,3) -> Accessories | M3: =VLOOKUP(Table2[[#This Row],[AgentID]],Sales_Agents!$A$1:C6,2) -> Chinedu | N3: =VLOOKUP(Table2[[#This Row],[AgentID]],Sales_Agents!$A$1:C6,3) -> South
A4: 3 | B4: 45562 | C4: =TEXT(Table2[[#This Row],[OrderDate]],"mmm") -> Sept | D4: 3 | E4: 4 | F4: 4 | G4: 55889 | H4: =G4*F4 -> 223556 | I4: =Table2[[#This Row],[Total Revenue]]*0.3 -> 67066.8 | J4: =I4/H4 -> 0.3 | K4: =VLOOKUP(Table2[[#This Row],[ProductID]],Products!$A$1:C8,2) -> Tablet | L4: =VLOOKUP(D4,Products!$A$1:C8,3) -> Electronics | M4: =VLOOKUP(Table2[[#This Row],[AgentID]],Sales_Agents!$A$1:C7,2) -> Zainab | N4: =VLOOKUP(Table2[[#This Row],[AgentID]],Sales_Agents!$A$1:C7,3) -> North
A5: 4 | B5: 45341 | C5: =TEXT(Table2[[#This Row],[OrderDate]],"mmm") -> Feb | D5: 3 | E5: 4 | F5: 7 | G5: 390956 | H5: =G5*F5 -> 2736692 | I5: =Table2[[#This Row],[Total Revenue]]*0.3 -> 821007.6 | J5: =I5/H5 -> 0.3 | K5: =VLOOKUP(Table2[[#This Row],[ProductID]],Products!$A$1:C9,2) -> Tablet | L5: =VLOOKUP(D5,Products!$A$1:C9,3) -> Electronics | M5: =VLOOKUP(Table2[[#This Row],[AgentID]],Sales_Agents!$A$1:C8,2) -> Zainab | N5: =VLOOKUP(Table2[[#This Row],[AgentID]],Sales_Agents!$A$1:C8,3) -> North
A6: 5 | B6: 45404 | C6: =TEXT(Table2[[#This Row],[OrderDate]],"mmm") -> Apr | D6: 1 | E6: 1 | F6: 16 | G6: 67730 | H6: =G6*F6 -> 1083680 | I6: =Table2[[#This Row],[Total Revenue]]*0.3 -> 325104 | J6: =I6/H6 -> 0.3 | K6: =VLOOKUP(Table2[[#This Row],[ProductID]],Products!$A$1:C10,2) -> Laptop | L6: =VLOOKUP(D6,Products!$A$1:C10,3) -> Electronics | M6: =VLOOKUP(Table2[[#This Row],[AgentID]],Sales_Agents!$A$1:C9,2) -> Akin | N6: =VLOOKUP(Table2[[#This Row],[AgentID]],Sales_Agents!$A$1:C9,3) -> West
A7: 6 | B7: 45453 | C7: =TEXT(Table2[[#This Row],[OrderDate]],"mmm") -> Jun | D7: 4 | E7: 2 | F7: 12 | G7: 210426 | H7: =G7*F7 -> 2525112 | I7: =Table2[[#This Row],[Total Revenue]]*0.3 -> 757533.6 | J7: =I7/H7 -> 0.3 | K7: =VLOOKUP(Table2[[#This Row],[ProductID]],Products!$A$1:C11,2) -> Printer | L7: =VLOOKUP(D7,Products!$A$1:C11,3) -> Accessories | M7: =VLOOKUP(Table2[[#This Row],[AgentID]],Sales_Agents!$A$1:C10,2) -> Blessing | N7: =VLOOKUP(Table2[[#This Row],[AgentID]],Sales_Agents!$A$1:C10,3) -> East
A8: 7 | B8: 45649 | C8: =TEXT(Table2[[#This Row],[OrderDate]],"mmm") -> Dec | D8: 3 | E8: 1 | F8: 3 | G8: 120353 | H8: =G8*F8 -> 361059 | I8: =Table2[[#This Row],[Total Revenue]]*0.3 -> 108317.7 | J8: =I8/H8 -> 0.3 | K8: =VLOOKUP(Table2[[#This Row],[ProductID]],Products!$A$1:C12,2) -> Tablet | L8: =VLOOKUP(D8,Products!$A$1:C12,3) -> Electronics | M8: =VLOOKUP(Table2[[#This Row],[AgentID]],Sales_Agents!$A$1:C11,2) -> Akin | N8: =VLOOKUP(Table2[[#This Row],[AgentID]],Sales_Agents!$A$1:C11,3) -> West
A9: 8 | B9: 45352 | C9: =TEXT(Table2[[#This Row],[OrderDate]],"mmm") -> Mar | D9: 1 | E9: 4 | F9: 20 | G9: 59988 | H9: =G9*F9 -> 1199760 | I9: =Table2[[#This Row],[Total Revenue]]*0.3 -> 359928 | J9: =I9/H9 -> 0.3 | K9: =VLOOKUP(Table2[[#This Row],[ProductID]],Products!$A$1:C13,2) -> Laptop | L9: =VLOOKUP(D9,Products!$A$1:C13,3) -> Electronics | M9: =VLOOKUP(Table2[[#This Row],[AgentID]],Sales_Agents!$A$1:C12,2) -> Zainab | N9: =VLOOKUP(Table2[[#This Row],[AgentID]],Sales_Agents!$A$1:C12,3) -> North
A10: 9 | B10: 45460 | C10: =TEXT(Table2[[#This Row],[OrderDate]],"mmm") -> Jun | D10: 4 | E10: 2 | F10: 16 | G10: 97381 | H10: =G10*F10 -> 1558096 | I10: =Table2[[#This Row],[Total Revenue]]*0.3 -> 467428.8 | J10: =I10/H10 -> 0.3 | K10: =VLOOKUP(Table2[[#This Row],[ProductID]],Products!$A$1:C14,2) -> Printer | L10: =VLOOKUP(D10,Products!$A$1:C14,3) -> Accessories | M10: =VLOOKUP(Table2[[#This Row],[AgentID]],Sales_Agents!$A$1:C13,2) -> Blessing | N10: =VLOOKUP(Table2[[#This Row],[AgentID]],Sales_Agents!$A$1:C13,3) -> East
A11: 10 | B11: 45347 | C11: =TEXT(Table2[[#This Row],[OrderDate]],"mmm") -> Feb | D11: 3 | E11: 1 | F11: 5 | G11: 111122 | H11: =G11*F11 -> 555610 | I11: =Table2[[#This Row],[Total Revenue]]*0.3 -> 166683 | J11: =I11/H11 -> 0.3 | K11: =VLOOKUP(Table2[[#This Row],[ProductID]],Products!$A$1:C15,2) -> Tablet | L11: =VLOOKUP(D11,Products!$A$1:C15,3) -> Electronics | M11: =VLOOKUP(Table2[[#This Row],[AgentID]],Sales_Agents!$A$1:C14,2) -> Akin | N11: =VLOOKUP(Table2[[#This Row],[AgentID]],Sales_Agents!$A$1:C14,3) -> West
A12: 11 | B12: 45489 | C12: =TEXT(Table2[[#This Row],[OrderDate]],"mmm") -> Jul | D12: 1 | E12: 1 | F12: 10 | G12: 67075 | H12: =G12*F12 -> 670750 | I12: =Table2[[#This Row],[Total Revenue]]*0.3 -> 201225 | J12: =I12/H12 -> 0.3 | K12: =VLOOKUP(Table2[[#This Row],[ProductID]],Products!$A$1:C16,2) -> Laptop | L12: =VLOOKUP(D12,Products!$A$1:C16,3) -> Electronics | M12: =VLOOKUP(Table2[[#This Row],[AgentID]],Sales_Agents!$A$1:C15,2) -> Akin | N12: =VLOOKUP(Table2[[#This Row],[AgentID]],Sales_Agents!$A$1:C15,3) -> West
A13: 12 | B13: 45543 | C13: =TEXT(Table2[[#This Row],[OrderDate]],"mmm") -> Sept | D13: 1 | E13: 3 | F13: 6 | G13: 234375 | H13: =G13*F13 -> 1406250 | I13: =Table2[[#This Row],[Total Revenue]]*0.3 -> 421875 | J13: =I13/H13 -> 0.3 | K13: =VLOOKUP(Table2[[#This Row],[ProductID]],Products!$A$1:C17,2) -> Laptop | L13: =VLOOKUP(D13,Products!$A$1:C17,3) -> Electronics | M13: =VLOOKUP(Table2[[#This Row],[AgentID]],Sales_Agents!$A$1:C16,2) -> Chinedu | N13: =VLOOKUP(Table2[[#This Row],[AgentID]],Sales_Agents!$A$1:C16,3) -> South
... A1201: 1200 | B1201: 45623 | C1201: =TEXT(Table2[[#This Row],[OrderDate]],"mmm") -> Nov | D1201: 1 | E1201: 2 | F1201: 12 | G1201: 202886 | H1201: =G1201*F1201 -> 2434632 | I1201: =Table2[[#This Row],[Total Revenue]]*0.3 -> 730389.6 | J1201: =I1201/H1201 -> 0.3 | K1201: =VLOOKUP(Table2[[#This Row],[ProductID]],Products!$A$1:C1205,2) -> Laptop | L1201: =VLOOKUP(D1201,Products!$A$1:C1205,3) -> Electronics | M1201: =VLOOKUP(Table2[[#This Row],[AgentID]],Sales_Agents!$A$1:C1204,2) -> Blessing | N1201: =VLOOKUP(Table2[[#This Row],[AgentID]],Sales_Agents!$A$1:C1204,3) -> East

Sheet Products
A1: ProductID | B1: ProductName | C1: Category
A2: 1 | B2: Laptop | C2: Electronics
A3: 2 | B3: Phone | C3: Electronics
A4: 3 | B4: Tablet | C4: Electronics
A5: 4 | B5: Printer | C5: Accessories
A6: 5 | B6: Monitor | C6: Accessories

Sheet Sales_Agents
A1: AgentID | B1: AgentName | C1: Region
A2: 1 | B2: Akin | C2: West
A3: 2 | B3: Blessing | C3: East
A4: 3 | B4: Chinedu | C4: South
A5: 4 | B5: Zainab | C5: North

Sheet PIVOT TABLE
A2: TOTAL REVENUE BY REGION AND PRODUCT
A3: Sum of Total Revenue | B3: Column Labels | O3: [>=1000000]₦#,##0,,"M";[>=1000]₦#,##0,"K";₦#,##0
A4: Row Labels | B4: East | C4: North | D4: South | E4: West | F4: Grand Total
A5: Laptop | B5: 135114248 | C5: 135348898 | D5: 110747873 | E5: 194940779 | F5: 576151798
A6: Monitor | B6: 171264183 | C6: 143218230 | D6: 123945634 | E6: 82211287 | F6: 520639334
A7: Phone | B7: 147645626 | C7: 133735871 | D7: 128323943 | E7: 143029406 | F7: 552734846
A8: Printer | B8: 190194034 | C8: 126851887 | D8: 137660869 | E8: 179323048 | F8: 634029838
A9: Tablet | B9: 137392068 | C9: 136583452 | D9: 113315361 | E9: 160344422 | F9: 547635303
A10: Grand Total | B10: 781610159 | C10: 675738338 | D10: 613993680 | E10: 759848942 | F10: 2831191119
A14: TOTAL REVENUE BY SALES AGENT
A15: Row Labels | B15: Sum of Total Revenue
A16: Blessing | B16: 781610159
A17: Akin | B17: 759848942
A18: Zainab | B18: 675738338
A19: Chinedu | B19: 613993680
A20: Grand Total | B20: 2831191119
A23: TOTAL REVENUE BY MONTHS
A24: Row Labels | B24: Sum of Total Revenue
A25: Jan | B25: 232061636
A26: Feb | B26: 234067539
A27: Mar | B27: 242474596
A28: Apr | B28: 280748080
A29: May | B29: 222073801
A30: Jun | B30: 232851945
A31: Jul | B31: 236002916
A32: Aug | B32: 210466725
A33: Sept | B33: 234322535
A34: Oct | B34: 238591314
A35: Nov | B35: 235752047
A36: Dec | B36: 231777985
A37: Grand Total | B37: 2831191119
A40: PRODUCTS BY THEIR GROSS PROFIT
A41: Row Labels | B41: Sum of Gross Profit By 30%
A42: Printer | B42: 0.22394456
A43: Laptop | B43: 0.20350156
A44: Phone | B44: 0.1952305
A45: Tablet | B45: 0.1934293
A46: Monitor | B46: 0.1838941
A47: Grand Total | B47: 1
A51: Row Labels | B51: Sum of Profit Margin | C51: Count of Quantity | D51: Sum of Gross Profit By 30%
...

Sheet DASHBOARD

Sheet Dates
A1: Date | B1: Month | C1: Year
A2: 45292 | B2: January | C2: 2024
A3: 45293 | B3: January | C3: 2024
A4: 45294 | B4: January | C4: 2024
A5: 45295 | B5: January | C5: 2024
A6: 45296 | B6: January | C6: 2024
A7: 45297 | B7: January | C7: 2024
A8: 45298 | B8: January | C8: 2024
A9: 45299 | B9: January | C9: 2024
A10: 45300 | B10: January | C10: 2024
A11: 45301 | B11: January | C11: 2024
A12: 45302 | B12: January | C12: 2024
A13: 45303 | B13: January | C13: 2024
... A366: 45656 | B366: December | C366: 2024
